conformant = "Unsupported"
notes = """
Support for TypeAliasType is not implemented.
"""
output = """
aliases_typealiastype.py:17:41 Undefined attribute [16]: `list` has no attribute `__getitem__`.
aliases_typealiastype.py:22:13 Incompatible parameter type [6]: In call `typing.GenericMeta.__getitem__`, for 1st positional argument, expected `Tuple[typing.Any, Type[Variable[$synthetic_attribute_resolution_variable]]]` but got `Tuple[ParamSpec, TypeVar]`.
aliases_typealiastype.py:22:65 Undefined attribute [16]: `tuple` has no attribute `__getitem__`.
aliases_typealiastype.py:32:6 Undefined attribute [16]: `TypeAliasType` has no attribute `other_attrib`.
aliases_typealiastype.py:35:4 Undefined or invalid type [11]: Annotation `GoodAlias4` is not defined as a type.
aliases_typealiastype.py:37:4 Undefined or invalid type [11]: Annotation `GoodAlias5` is not defined as a type.
"""
conformance_automated = "Fail"
errors_diff = """
Line 40: Expected 1 errors
Line 43: Expected 1 errors
Line 44: Expected 1 errors
Line 45: Expected 1 errors
Line 46: Expected 1 errors
Line 47: Expected 1 errors
Line 48: Expected 1 errors
Line 52: Expected 1 errors
Line 53: Expected 1 errors
Line 54: Expected 1 errors
Line 55: Expected 1 errors
Line 56: Expected 1 errors
Line 57: Expected 1 errors
Line 58: Expected 1 errors
Line 59: Expected 1 errors
Line 60: Expected 1 errors
Line 61: Expected 1 errors
Line 62: Expected 1 errors
Line 63: Expected 1 errors
Line 64: Expected 1 errors
Line 17: Unexpected errors ['aliases_typealiastype.py:17:41 Undefined attribute [16]: `list` has no attribute `__getitem__`.']
Line 22: Unexpected errors ['aliases_typealiastype.py:22:13 Incompatible parameter type [6]: In call `typing.GenericMeta.__getitem__`, for 1st positional argument, expected `Tuple[typing.Any, Type[Variable[$synthetic_attribute_resolution_variable]]]` but got `Tuple[ParamSpec, TypeVar]`.', 'aliases_typealiastype.py:22:65 Undefined attribute [16]: `tuple` has no attribute `__getitem__`.']
Line 35: Unexpected errors ['aliases_typealiastype.py:35:4 Undefined or invalid type [11]: Annotation `GoodAlias4` is not defined as a type.']
Line 37: Unexpected errors ['aliases_typealiastype.py:37:4 Undefined or invalid type [11]: Annotation `GoodAlias5` is not defined as a type.']
"""
