conformant = "Partial"
notes = """
Does not report errors during binding to self parameter of __init__ method.
Does not infer type of Self for self parameter of __init__ method.
Rejects valid type annotation for self parameter in __init__ method.
Does not support function-scoped TypeVars in self annotation in __init__ method.
Does not reject use of class-scoped type variables in annotation of self parameter in __init__ method.
"""
conformance_automated = "Fail"
errors_diff = """
Line 21: Expected 1 errors
Line 42: Expected 1 errors
Line 56: Expected 1 errors
Line 107: Expected 1 errors
Line 51: Unexpected errors ["constructors_call_init.py:51:1: \\x1b[1m\\x1b[31merror\\x1b[39m\\x1b[0m: in __init__: Invalid type annotation 'Class4[int]' for self [invalid-annotation]"]
Line 72: Unexpected errors ['constructors_call_init.py:72:1: \\x1b[1m\\x1b[31merror\\x1b[39m\\x1b[0m: in <module>: Class5 [assert-type]']
Line 74: Unexpected errors ['constructors_call_init.py:74:1: \\x1b[1m\\x1b[31merror\\x1b[39m\\x1b[0m: in <module>: Class5 [assert-type]']
Line 88: Unexpected errors ["constructors_call_init.py:88:5: \\x1b[1m\\x1b[31merror\\x1b[39m\\x1b[0m: in Class6: Invalid type annotation 'V2'  [invalid-annotation]", "constructors_call_init.py:88:5: \\x1b[1m\\x1b[31merror\\x1b[39m\\x1b[0m: in Class6: Invalid type annotation 'V1'  [invalid-annotation]", "constructors_call_init.py:88:1: \\x1b[1m\\x1b[31merror\\x1b[39m\\x1b[0m: in __init__: Invalid type annotation 'Class6[V1, V2]' for self [invalid-annotation]"]
Line 91: Unexpected errors ['constructors_call_init.py:91:1: \\x1b[1m\\x1b[31merror\\x1b[39m\\x1b[0m: in <module>: Class6 [assert-type]']
Line 96: Unexpected errors ["constructors_call_init.py:96:5: \\x1b[1m\\x1b[31merror\\x1b[39m\\x1b[0m: in Class7: Invalid type annotation 'V2'  [invalid-annotation]", "constructors_call_init.py:96:5: \\x1b[1m\\x1b[31merror\\x1b[39m\\x1b[0m: in Class7: Invalid type annotation 'V1'  [invalid-annotation]", "constructors_call_init.py:96:1: \\x1b[1m\\x1b[31merror\\x1b[39m\\x1b[0m: in __init__: Invalid type annotation 'Class7[V2, V1]' for self [invalid-annotation]"]
Line 99: Unexpected errors ['constructors_call_init.py:99:1: \\x1b[1m\\x1b[31merror\\x1b[39m\\x1b[0m: in <module>: Class7 [assert-type]']
Line 108: Unexpected errors ["constructors_call_init.py:108:9: \\x1b[1m\\x1b[31merror\\x1b[39m\\x1b[0m: in __init__: Invalid type annotation 'Class8[T2, T1]' for self [invalid-annotation]"]
"""
output = """
constructors_call_init.py:51:1: \u001b[1m\u001b[31merror\u001b[39m\u001b[0m: in __init__: Invalid type annotation 'Class4[int]' for self [invalid-annotation]

    def __init__(self: "Class4[int]") -> None: ...
\u001b[1m\u001b[31m\u001b[39m\u001b[0m

constructors_call_init.py:72:1: \u001b[1m\u001b[31merror\u001b[39m\u001b[0m: in <module>: Class5 [assert-type]

assert_type(Class5(0), Class5[list[int]])
\u001b[1m\u001b[31m~~~~~~~~~~~~~~~~~~~~~~~~~~~~~~~~~~~~~~~~~\u001b[39m\u001b[0m

constructors_call_init.py:74:1: \u001b[1m\u001b[31merror\u001b[39m\u001b[0m: in <module>: Class5 [assert-type]

assert_type(Class5(""), Class5[set[str]])
\u001b[1m\u001b[31m~~~~~~~~~~~~~~~~~~~~~~~~~~~~~~~~~~~~~~~~~\u001b[39m\u001b[0m

constructors_call_init.py:88:5: \u001b[1m\u001b[31merror\u001b[39m\u001b[0m: in Class6: Invalid type annotation 'V2'  [invalid-annotation]

    def __init__(self: "Class6[V1, V2]", value1: V1, value2: V2) -> None: ...
    \u001b[1m\u001b[31m~~~~~~~~~~~~~~~~~~~~~~~~~~~~~~~~~~~~~~~~~~~~~~~~~~~~~~~~~~~~~~~~~~~~~~~~~\u001b[39m\u001b[0m

constructors_call_init.py:88:5: \u001b[1m\u001b[31merror\u001b[39m\u001b[0m: in Class6: Invalid type annotation 'V1'  [invalid-annotation]

    def __init__(self: "Class6[V1, V2]", value1: V1, value2: V2) -> None: ...
    \u001b[1m\u001b[31m~~~~~~~~~~~~~~~~~~~~~~~~~~~~~~~~~~~~~~~~~~~~~~~~~~~~~~~~~~~~~~~~~~~~~~~~~\u001b[39m\u001b[0m

constructors_call_init.py:88:1: \u001b[1m\u001b[31merror\u001b[39m\u001b[0m: in __init__: Invalid type annotation 'Class6[V1, V2]' for self [invalid-annotation]

    def __init__(self: "Class6[V1, V2]", value1: V1, value2: V2) -> None: ...
\u001b[1m\u001b[31m\u001b[39m\u001b[0m

constructors_call_init.py:91:1: \u001b[1m\u001b[31merror\u001b[39m\u001b[0m: in <module>: Class6 [assert-type]

assert_type(Class6(0, ""), Class6[int, str])
\u001b[1m\u001b[31m~~~~~~~~~~~~~~~~~~~~~~~~~~~~~~~~~~~~~~~~~~~~\u001b[39m\u001b[0m

constructors_call_init.py:96:5: \u001b[1m\u001b[31merror\u001b[39m\u001b[0m: in Class7: Invalid type annotation 'V2'  [invalid-annotation]

    def __init__(self: "Class7[V2, V1]", value1: V1, value2: V2) -> None: ...
    \u001b[1m\u001b[31m~~~~~~~~~~~~~~~~~~~~~~~~~~~~~~~~~~~~~~~~~~~~~~~~~~~~~~~~~~~~~~~~~~~~~~~~~\u001b[39m\u001b[0m

constructors_call_init.py:96:5: \u001b[1m\u001b[31merror\u001b[39m\u001b[0m: in Class7: Invalid type annotation 'V1'  [invalid-annotation]

    def __init__(self: "Class7[V2, V1]", value1: V1, value2: V2) -> None: ...
    \u001b[1m\u001b[31m~~~~~~~~~~~~~~~~~~~~~~~~~~~~~~~~~~~~~~~~~~~~~~~~~~~~~~~~~~~~~~~~~~~~~~~~~\u001b[39m\u001b[0m

constructors_call_init.py:96:1: \u001b[1m\u001b[31merror\u001b[39m\u001b[0m: in __init__: Invalid type annotation 'Class7[V2, V1]' for self [invalid-annotation]

    def __init__(self: "Class7[V2, V1]", value1: V1, value2: V2) -> None: ...
\u001b[1m\u001b[31m\u001b[39m\u001b[0m

constructors_call_init.py:99:1: \u001b[1m\u001b[31merror\u001b[39m\u001b[0m: in <module>: Class7 [assert-type]

assert_type(Class7(0, ""), Class7[str, int])
\u001b[1m\u001b[31m~~~~~~~~~~~~~~~~~~~~~~~~~~~~~~~~~~~~~~~~~~~~\u001b[39m\u001b[0m

constructors_call_init.py:108:9: \u001b[1m\u001b[31merror\u001b[39m\u001b[0m: in __init__: Invalid type annotation 'Class8[T2, T1]' for self [invalid-annotation]

        pass
        \u001b[1m\u001b[31m~~~~\u001b[39m\u001b[0m

constructors_call_init.py:130:1: \u001b[1m\u001b[31merror\u001b[39m\u001b[0m: in <module>: Function Class11.__init__ expects 1 arg(s), got 2 [wrong-arg-count]

Class11(1)  # E
\u001b[1m\u001b[31m~~~~~~~~~~\u001b[39m\u001b[0m

"""
