conformant = "Unsupported"
notes = """
Does not understand descriptor objects in dataclass.
"""
output = """
dataclasses_descriptors.py:24:9: \u001b[1m\u001b[31merror\u001b[39m\u001b[0m: in __get__: bad return type [bad-return-type]

        ...
        \u001b[1m\u001b[31m~~~\u001b[39m\u001b[0m

Called from (traceback):
  line 38, in current file
dataclasses_descriptors.py:24:9: \u001b[1m\u001b[31merror\u001b[39m\u001b[0m: in __get__: bad return type [bad-return-type]

        ...
        \u001b[1m\u001b[31m~~~\u001b[39m\u001b[0m

Called from (traceback):
  line 37, in current file
dataclasses_descriptors.py:35:7: \u001b[1m\u001b[31merror\u001b[39m\u001b[0m: in <module>: Function DC1.__init__ was called with the wrong arguments [wrong-arg-types]

dc1 = DC1(3)
      \u001b[1m\u001b[31m~~~~~~\u001b[39m\u001b[0m

dataclasses_descriptors.py:51:9: \u001b[1m\u001b[31merror\u001b[39m\u001b[0m: in __get__: bad return type [bad-return-type]

        ...
        \u001b[1m\u001b[31m~~~\u001b[39m\u001b[0m

Called from (traceback):
  line 68, in current file
dataclasses_descriptors.py:51:9: \u001b[1m\u001b[31merror\u001b[39m\u001b[0m: in __get__: bad return type [bad-return-type]

        ...
        \u001b[1m\u001b[31m~~~\u001b[39m\u001b[0m

Called from (traceback):
  line 67, in current file
dataclasses_descriptors.py:51:9: \u001b[1m\u001b[31merror\u001b[39m\u001b[0m: in __get__: bad return type [bad-return-type]

        ...
        \u001b[1m\u001b[31m~~~\u001b[39m\u001b[0m

Called from (traceback):
  line 66, in current file
dataclasses_descriptors.py:51:9: \u001b[1m\u001b[31merror\u001b[39m\u001b[0m: in __get__: bad return type [bad-return-type]

        ...
        \u001b[1m\u001b[31m~~~\u001b[39m\u001b[0m

Called from (traceback):
  line 63, in current file
dataclasses_descriptors.py:51:9: \u001b[1m\u001b[31merror\u001b[39m\u001b[0m: in __get__: bad return type [bad-return-type]

        ...
        \u001b[1m\u001b[31m~~~\u001b[39m\u001b[0m

Called from (traceback):
  line 62, in current file
dataclasses_descriptors.py:51:9: \u001b[1m\u001b[31merror\u001b[39m\u001b[0m: in __get__: bad return type [bad-return-type]

        ...
        \u001b[1m\u001b[31m~~~\u001b[39m\u001b[0m

Called from (traceback):
  line 61, in current file
dataclasses_descriptors.py:51:9: \u001b[1m\u001b[31merror\u001b[39m\u001b[0m: in __get__: bad return type [bad-return-type]

        ...
        \u001b[1m\u001b[31m~~~\u001b[39m\u001b[0m

"""
conformance_automated = "Fail"
errors_diff = """
Line 24: Unexpected errors ['dataclasses_descriptors.py:24:9: \\x1b[1m\\x1b[31merror\\x1b[39m\\x1b[0m: in __get__: bad return type [bad-return-type]', 'dataclasses_descriptors.py:24:9: \\x1b[1m\\x1b[31merror\\x1b[39m\\x1b[0m: in __get__: bad return type [bad-return-type]']
Line 35: Unexpected errors ['dataclasses_descriptors.py:35:7: \\x1b[1m\\x1b[31merror\\x1b[39m\\x1b[0m: in <module>: Function DC1.__init__ was called with the wrong arguments [wrong-arg-types]']
Line 51: Unexpected errors ['dataclasses_descriptors.py:51:9: \\x1b[1m\\x1b[31merror\\x1b[39m\\x1b[0m: in __get__: bad return type [bad-return-type]', 'dataclasses_descriptors.py:51:9: \\x1b[1m\\x1b[31merror\\x1b[39m\\x1b[0m: in __get__: bad return type [bad-return-type]', 'dataclasses_descriptors.py:51:9: \\x1b[1m\\x1b[31merror\\x1b[39m\\x1b[0m: in __get__: bad return type [bad-return-type]', 'dataclasses_descriptors.py:51:9: \\x1b[1m\\x1b[31merror\\x1b[39m\\x1b[0m: in __get__: bad return type [bad-return-type]', 'dataclasses_descriptors.py:51:9: \\x1b[1m\\x1b[31merror\\x1b[39m\\x1b[0m: in __get__: bad return type [bad-return-type]', 'dataclasses_descriptors.py:51:9: \\x1b[1m\\x1b[31merror\\x1b[39m\\x1b[0m: in __get__: bad return type [bad-return-type]', 'dataclasses_descriptors.py:51:9: \\x1b[1m\\x1b[31merror\\x1b[39m\\x1b[0m: in __get__: bad return type [bad-return-type]']
"""
